<?xml version="1.0" ?>
<!-- =================================================================================== -->
<!-- |    This document was autogenerated by xacro from fish_hpurv_macro.urdf.xacro    | -->
<!-- |    EDITING THIS FILE BY HAND IS NOT RECOMMENDED                                 | -->
<!-- =================================================================================== -->
<robot name="fish_hpurv">
  <link name="link_base">
    <inertial>
      <origin rpy="1.57 0 0" xyz="0.0325815 0.0493006 -0.0204279"/>
      <mass value="12"/>
      <!-- assume base mass remains 12 kg -->
      <inertia ixx="0.01" ixy="0" ixz="0" iyy="0.01" iyz="0" izz="0.01"/>
    </inertial>
    <visual>
      <origin rpy="1.57 0 0" xyz="0.0325815 0.0493006 0.02"/>
      <geometry>
        <mesh filename="/home/uav/ros2_ws/install/fish_hpurv/share/fish_hpurv/meshes/link_base.stl"/>
      </geometry>
      <material name="link_base_material">
        <color rgba="0.796078 0.823529 0.937255 1.0"/>
      </material>
    </visual>
    <collision>
      <origin rpy="1.57 0 0" xyz="0.0325815 0.0493006 -0.0204279"/>
      <geometry>
        <mesh filename="/home/uav/ros2_ws/install/fish_hpurv/share/fish_hpurv/meshes/link_base.stl"/>
      </geometry>
    </collision>
  </link>
  <link name="link_caudal">
    <inertial>
      <origin rpy="1.5708 0 0" xyz="-0.378805 0 -0.05"/>
      <mass value="0.2"/>
      <inertia ixx="0.005" ixy="0" ixz="0" iyy="0.005" iyz="0" izz="0.005"/>
    </inertial>
    <visual>
      <origin rpy="1.5708 0 0" xyz="-0.378805 0 -0.05"/>
      <geometry>
        <mesh filename="/home/uav/ros2_ws/install/fish_hpurv/share/fish_hpurv/meshes/link_caudal.stl"/>
      </geometry>
      <material name="link_caudal_material">
        <color rgba="0.796078 0.823529 0.937255 1.0"/>
      </material>
    </visual>
    <collision>
      <origin rpy="1.5708 0 0" xyz="-0.378805 0 -0.05"/>
      <geometry>
        <mesh filename="/home/uav/ros2_ws/install/fish_hpurv/share/fish_hpurv/meshes/link_caudal.stl"/>
      </geometry>
    </collision>
  </link>
  <joint name="caudal_joint" type="revolute">
    <origin rpy="0 0 0" xyz="0.425323 0.05 0.06"/>
    <parent link="link_base"/>
    <child link="link_caudal"/>
    <axis xyz="0 0 1"/>
    <limit effort="10" lower="-0.523599" upper="0.523599" velocity="10"/>
  </joint>
  <link name="link_pectoral_left">
    <inertial>
      <origin rpy="3.14 0 0" xyz="0.0829833 -0.0470575 0.13"/>
      <mass value="0.1"/>
      <inertia ixx="0.001" ixy="0" ixz="0" iyy="0.001" iyz="0" izz="0.001"/>
    </inertial>
    <visual>
      <origin rpy="3.14 0 0" xyz="0.0829833 -0.0470575 0.13"/>
      <geometry>
        <mesh filename="/home/uav/ros2_ws/install/fish_hpurv/share/fish_hpurv/meshes/link_pectoral_left.stl"/>
      </geometry>
      <material name="link_pectoral_left_material">
        <color rgba="0.796078 0.823529 0.937255 1.0"/>
      </material>
    </visual>
    <collision>
      <origin rpy="3.14 0 0" xyz="0.0829833 -0.0470575 0.13"/>
      <geometry>
        <mesh filename="/home/uav/ros2_ws/install/fish_hpurv/share/fish_hpurv/meshes/link_pectoral_left.stl"/>
      </geometry>
    </collision>
  </link>
  <joint name="joint1" type="revolute">
    <origin rpy="1.57 0 0" xyz="-0.05 0.18 0.035"/>
    <parent link="link_base"/>
    <child link="link_pectoral_left"/>
    <axis xyz="0 0 1"/>
    <limit effort="10" lower="-0.785398" upper="0.785398" velocity="10"/>
  </joint>
  <link name="link_pectoral_right">
    <inertial>
      <origin rpy="0 0 0" xyz="0.0829833 0.0470575 0.13"/>
      <mass value="0.1"/>
      <inertia ixx="0.001" ixy="0" ixz="0" iyy="0.001" iyz="0" izz="0.001"/>
    </inertial>
    <visual>
      <origin rpy="0 0 0" xyz="0.0829833 0.0470575 0.13"/>
      <geometry>
        <mesh filename="/home/uav/ros2_ws/install/fish_hpurv/share/fish_hpurv/meshes/link_pectoral_right.stl"/>
      </geometry>
      <material name="link_pectoral_right_material">
        <color rgba="0.796078 0.823529 0.937255 1.0"/>
      </material>
    </visual>
    <collision>
      <origin rpy="0 0 0" xyz="0.0829833 0.0470575 0.13"/>
      <geometry>
        <mesh filename="/home/uav/ros2_ws/install/fish_hpurv/share/fish_hpurv/meshes/link_pectoral_right.stl"/>
      </geometry>
    </collision>
  </link>
  <joint name="joint2" type="revolute">
    <origin rpy="-1.57 0 0" xyz="-0.05 -0.08 0.035"/>
    <parent link="link_base"/>
    <child link="link_pectoral_right"/>
    <axis xyz="0 0 1"/>
    <limit effort="10" lower="-0.785398" upper="0.785398" velocity="10"/>
  </joint>
  <joint name="laser_joint" type="fixed">
    <parent link="link_base"/>
    <child link="laser_frame"/>
    <origin rpy="0 0 0" xyz="0.0325815 0.0493006 0.02"/>
  </joint>
  <link name="laser_frame">
    <inertial>
      <origin rpy="0 0 0" xyz="0 0 0"/>
      <mass value="0.1"/>
      <inertia ixx="0.0001" ixy="0" ixz="0" iyy="0.0001" iyz="0" izz="0.0001"/>
    </inertial>
    <visual>
      <origin rpy="0 0 0" xyz="0 0 0"/>
      <geometry>
        <cylinder length="0.04" radius="0.05"/>
      </geometry>
      <material name="red">
        <color rgba="1 0 0 1"/>
      </material>
    </visual>
    <collision>
      <origin rpy="0 0 0" xyz="0 0 0"/>
      <geometry>
        <cylinder length="0.04" radius="0.05"/>
      </geometry>
    </collision>
  </link>
  <gazebo reference="laser_frame">
    <material>Gazebo/Red</material>
    <sensor name="laser" type="ray">
      <pose>0 0 0 0 0 0</pose>
      <visualize>true</visualize>
      <update_rate>10</update_rate>
      <ray>
        <scan>
          <horizontal>
            <samples>360</samples>
            <min_angle>-3.14</min_angle>
            <max_angle>3.14</max_angle>
          </horizontal>
        </scan>
        <range>
          <min>0.3</min>
          <max>12</max>
        </range>
      </ray>
      <plugin filename="libgazebo_ros_laser.so" name="laser_controller">
        <ros>
          <argument>~/out:=/scan</argument>
        </ros>
        <output_type>sensor_msgs/LaserScan</output_type>
        <frame_name>laser_frame</frame_name>
      </plugin>
    </sensor>
  </gazebo>
  <joint name="imu_joint" type="fixed">
    <parent link="link_base"/>
    <child link="imu_link"/>
    <origin rpy="0 0 0" xyz="0.0325815 0.0493006 0.02"/>
  </joint>
  <link name="imu_link">
    <inertial>
      <origin rpy="0 0 0" xyz="0 0 0"/>
      <mass value="0.1"/>
      <inertia ixx="0.000001" ixy="0" ixz="0" iyy="0.000001" iyz="0" izz="0.000001"/>
    </inertial>
    <visual>
      <origin rpy="0 0 0" xyz="0 0 0"/>
      <geometry>
        <box size="0.01 0.01 0.01"/>
      </geometry>
      <material name="blue">
        <color rgba="0 0 1 1"/>
      </material>
    </visual>
    <collision>
      <origin rpy="0 0 0" xyz="0 0 0"/>
      <geometry>
        <box size="0.01 0.01 0.01"/>
      </geometry>
    </collision>
  </link>
  <gazebo reference="imu_link">
    <sensor name="imu_sensor" type="imu">
      <update_rate>50</update_rate>
      <always_on>true</always_on>
      <visualize>true</visualize>
      <plugin filename="libgazebo_ros_imu.so" name="imu_plugin">
        <ros>
          <argument>~/out:=/imu/data</argument>
        </ros>
        <topicName>/imu/data</topicName>
        <frameName>imu_link</frameName>
      </plugin>
    </sensor>
  </gazebo>
  <gazebo reference="link_base">
    <sensor name="dvl_sensor" type="ray">
      <pose>0.03 -0.085 -0.06  0  3.14 0</pose>
      <visualize>true</visualize>
      <update_rate>10</update_rate>
      <ray>
        <scan>
          <horizontal>
            <samples>4</samples>
            <min_angle>0</min_angle>
            <max_angle>6.28319</max_angle>
          </horizontal>
          <vertical>
            <samples>1</samples>
            <min_angle>1.2217</min_angle>
            <max_angle>1.2217</max_angle>
          </vertical>
        </scan>
        <range>
          <min>0.1</min>
          <max>100</max>
        </range>
      </ray>
      <plugin filename="libfish_dvl_plugin.so" name="custom_dvl_plugin"/>
    </sensor>
  </gazebo>
  <gazebo>
    <plugin filename="libBuoyancyPlugin.so" name="buoyancy_plugin">
      <fluid_density>1000</fluid_density>
      <link name="link_base">
        <volume>0.0122</volume>
        <center_of_volume>0.0325815 0.0493006 0.02</center_of_volume>
      </link>
      <link name="link_caudal">
        <volume>0.0002</volume>
        <center_of_volume>-0.378805 0 -0.05</center_of_volume>
      </link>
      <link name="link_pectoral_left">
        <volume>0.0001</volume>
        <center_of_volume>0.0829833 -0.0470575 0.13</center_of_volume>
      </link>
      <link name="link_pectoral_right">
        <volume>0.0001</volume>
        <center_of_volume>0.0829833 0.0470575 0.13</center_of_volume>
      </link>
    </plugin>
  </gazebo>
</robot>
